Traceback (most recent call last):
  File "/home/pi/.local/lib/python3.7/site-packages/aiohttp/connector.py", line 967, in _create_direct_connection
    traces=traces), loop=self._loop)
  File "/home/pi/.local/lib/python3.7/site-packages/aiohttp/connector.py", line 830, in _resolve_host
    self._resolver.resolve(host, port, family=self._family)
  File "/home/pi/.local/lib/python3.7/site-packages/aiohttp/resolver.py", line 30, in resolve
    host, port, type=socket.SOCK_STREAM, family=family)
  File "/usr/lib/python3.7/asyncio/base_events.py", line 789, in getaddrinfo
    None, getaddr_func, host, port, family, type, proto, flags)
  File "/usr/lib/python3.7/concurrent/futures/thread.py", line 57, in run
    result = self.fn(*self.args, **self.kwargs)
  File "/usr/lib/python3.7/socket.py", line 748, in getaddrinfo
    for res in _socket.getaddrinfo(host, port, family, type, proto, flags):
socket.gaierror: [Errno -3] Temporary failure in name resolution

The above exception was the direct cause of the following exception:

Traceback (most recent call last):
  File "hkiot.py", line 40, in <module>
    rtm_client.start()
  File "/home/pi/.local/lib/python3.7/site-packages/slack/rtm/client.py", line 198, in start
    return self._event_loop.run_until_complete(future)
  File "/usr/lib/python3.7/asyncio/base_events.py", line 584, in run_until_complete
    return future.result()
  File "/home/pi/.local/lib/python3.7/site-packages/slack/rtm/client.py", line 329, in _connect_and_read
    url, data = await self._retreive_websocket_info()
  File "/home/pi/.local/lib/python3.7/site-packages/slack/rtm/client.py", line 503, in _retreive_websocket_info
    resp = await self._web_client.rtm_connect()
  File "/home/pi/.local/lib/python3.7/site-packages/slack/web/base_client.py", line 214, in _send
    http_verb=http_verb, api_url=api_url, req_args=req_args
  File "/home/pi/.local/lib/python3.7/site-packages/slack/web/base_client.py", line 244, in _request
    async with session.request(http_verb, api_url, **req_args) as res:
  File "/home/pi/.local/lib/python3.7/site-packages/aiohttp/client.py", line 1012, in __aenter__
    self._resp = await self._coro
  File "/home/pi/.local/lib/python3.7/site-packages/aiohttp/client.py", line 483, in _request
    timeout=real_timeout
  File "/home/pi/.local/lib/python3.7/site-packages/aiohttp/connector.py", line 523, in connect
    proto = await self._create_connection(req, traces, timeout)
  File "/home/pi/.local/lib/python3.7/site-packages/aiohttp/connector.py", line 859, in _create_connection
    req, traces, timeout)
  File "/home/pi/.local/lib/python3.7/site-packages/aiohttp/connector.py", line 971, in _create_direct_connection
    raise ClientConnectorError(req.connection_key, exc) from exc
aiohttp.client_exceptions.ClientConnectorError: Cannot connect to host www.slack.com:443 ssl:default [Temporary failure in name resolution]
Unclosed client session
client_session: <aiohttp.client.ClientSession object at 0xb5b205d0>
